Workbook

Sheet How to answer
A1: Phoenix Skyblock · decisions
A2: Each row is a choice the game uses right now. Answer in the yellow column with one pick:
A3: Suggested = keep it as written in "Suggested".
A4: No = don't do it that way.
A5: Other = write what you want in "Note".
A6: Empty rows keep the suggested answer. Filter Priority = "before launch" to do the important ones first.
A7: Faster on a phone: the clickable page "Phoenix Skyblock Decisions" has the same questions with one tap per answer.
A9: Example of a filled row:
A10: Question | B10: Suggested | C10: Your answer | D10: Note
A11: Keep the AFK pool limit at 8 hours per day? | B11: Yes, 8 hours | C11: Other | D11: 6 hours

Sheet Summary
A1: Area | B1: Questions | C1: Answered | D1: Answered % | E1: Before launch | F1: Before launch answered
A2: Look & feel | B2: =COUNTIF(Questions!$B$2:$B$1014,A2) -> 112 | C2: =COUNTIFS(Questions!$B$2:$B$1014,A2,Questions!$F$2:$F$1014,"<>") -> 0 | D2: =IF(B2=0,0,C2/B2) -> 0 | E2: =COUNTIFS(Questions!$B$2:$B$1014,A2,Questions!$H$2:$H$1014,"before launch") -> 24 | F2: =COUNTIFS(Questions!$B$2:$B$1014,A2,Questions!$H$2:$H$1014,"before launch",Questions!$F$2:$F$1014,"<>") -> 0
A3: Profiles | B3: =COUNTIF(Questions!$B$2:$B$1014,A3) -> 25 | C3: =COUNTIFS(Questions!$B$2:$B$1014,A3,Questions!$F$2:$F$1014,"<>") -> 0 | D3: =IF(B3=0,0,C3/B3) -> 0 | E3: =COUNTIFS(Questions!$B$2:$B$1014,A3,Questions!$H$2:$H$1014,"before launch") -> 14 | F3: =COUNTIFS(Questions!$B$2:$B$1014,A3,Questions!$H$2:$H$1014,"before launch",Questions!$F$2:$F$1014,"<>") -> 0
A4: Islands | B4: =COUNTIF(Questions!$B$2:$B$1014,A4) -> 156 | C4: =COUNTIFS(Questions!$B$2:$B$1014,A4,Questions!$F$2:$F$1014,"<>") -> 0 | D4: =IF(B4=0,0,C4/B4) -> 0 | E4: =COUNTIFS(Questions!$B$2:$B$1014,A4,Questions!$H$2:$H$1014,"before launch") -> 57 | F4: =COUNTIFS(Questions!$B$2:$B$1014,A4,Questions!$H$2:$H$1014,"before launch",Questions!$F$2:$F$1014,"<>") -> 0
A5: Social & chat | B5: =COUNTIF(Questions!$B$2:$B$1014,A5) -> 30 | C5: =COUNTIFS(Questions!$B$2:$B$1014,A5,Questions!$F$2:$F$1014,"<>") -> 0 | D5: =IF(B5=0,0,C5/B5) -> 0 | E5: =COUNTIFS(Questions!$B$2:$B$1014,A5,Questions!$H$2:$H$1014,"before launch") -> 12 | F5: =COUNTIFS(Questions!$B$2:$B$1014,A5,Questions!$H$2:$H$1014,"before launch",Questions!$F$2:$F$1014,"<>") -> 0
A6: Teleports & essentials | B6: =COUNTIF(Questions!$B$2:$B$1014,A6) -> 23 | C6: =COUNTIFS(Questions!$B$2:$B$1014,A6,Questions!$F$2:$F$1014,"<>") -> 0 | D6: =IF(B6=0,0,C6/B6) -> 0 | E6: =COUNTIFS(Questions!$B$2:$B$1014,A6,Questions!$H$2:$H$1014,"before launch") -> 9 | F6: =COUNTIFS(Questions!$B$2:$B$1014,A6,Questions!$H$2:$H$1014,"before launch",Questions!$F$2:$F$1014,"<>") -> 0
A7: Ranks, perks & cosmetics | B7: =COUNTIF(Questions!$B$2:$B$1014,A7) -> 49 | C7: =COUNTIFS(Questions!$B$2:$B$1014,A7,Questions!$F$2:$F$1014,"<>") -> 0 | D7: =IF(B7=0,0,C7/B7) -> 0 | E7: =COUNTIFS(Questions!$B$2:$B$1014,A7,Questions!$H$2:$H$1014,"before launch") -> 14 | F7: =COUNTIFS(Questions!$B$2:$B$1014,A7,Questions!$H$2:$H$1014,"before launch",Questions!$F$2:$F$1014,"<>") -> 0
A8: Worlds & builds | B8: =COUNTIF(Questions!$B$2:$B$1014,A8) -> 12 | C8: =COUNTIFS(Questions!$B$2:$B$1014,A8,Questions!$F$2:$F$1014,"<>") -> 0 | D8: =IF(B8=0,0,C8/B8) -> 0 | E8: =COUNTIFS(Questions!$B$2:$B$1014,A8,Questions!$H$2:$H$1014,"before launch") -> 5 | F8: =COUNTIFS(Questions!$B$2:$B$1014,A8,Questions!$H$2:$H$1014,"before launch",Questions!$F$2:$F$1014,"<>") -> 0
A9: Staff & punishments | B9: =COUNTIF(Questions!$B$2:$B$1014,A9) -> 125 | C9: =COUNTIFS(Questions!$B$2:$B$1014,A9,Questions!$F$2:$F$1014,"<>") -> 0 | D9: =IF(B9=0,0,C9/B9) -> 0 | E9: =COUNTIFS(Questions!$B$2:$B$1014,A9,Questions!$H$2:$H$1014,"before launch") -> 37 | F9: =COUNTIFS(Questions!$B$2:$B$1014,A9,Questions!$H$2:$H$1014,"before launch",Questions!$F$2:$F$1014,"<>") -> 0
A10: Economy | B10: =COUNTIF(Questions!$B$2:$B$1014,A10) -> 196 | C10: =COUNTIFS(Questions!$B$2:$B$1014,A10,Questions!$F$2:$F$1014,"<>") -> 0 | D10: =IF(B10=0,0,C10/B10) -> 0 | E10: =COUNTIFS(Questions!$B$2:$B$1014,A10,Questions!$H$2:$H$1014,"before launch") -> 97 | F10: =COUNTIFS(Questions!$B$2:$B$1014,A10,Questions!$H$2:$H$1014,"before launch",Questions!$F$2:$F$1014,"<>") -> 0
A11: The Depths | B11: =COUNTIF(Questions!$B$2:$B$1014,A11) -> 85 | C11: =COUNTIFS(Questions!$B$2:$B$1014,A11,Questions!$F$2:$F$1014,"<>") -> 0 | D11: =IF(B11=0,0,C11/B11) -> 0 | E11: =COUNTIFS(Questions!$B$2:$B$1014,A11,Questions!$H$2:$H$1014,"before launch") -> 30 | F11: =COUNTIFS(Questions!$B$2:$B$1014,A11,Questions!$H$2:$H$1014,"before launch",Questions!$F$2:$F$1014,"<>") -> 0
A12: Tools, skills & enchants | B12: =COUNTIF(Questions!$B$2:$B$1014,A12) -> 99 | C12: =COUNTIFS(Questions!$B$2:$B$1014,A12,Questions!$F$2:$F$1014,"<>") -> 0 | D12: =IF(B12=0,0,C12/B12) -> 0 | E12: =COUNTIFS(Questions!$B$2:$B$1014,A12,Questions!$H$2:$H$1014,"before launch") -> 38 | F12: =COUNTIFS(Questions!$B$2:$B$1014,A12,Questions!$H$2:$H$1014,"before launch",Questions!$F$2:$F$1014,"<>") -> 0
A13: Wardrobe & sets | B13: =COUNTIF(Questions!$B$2:$B$1014,A13) -> 50 | C13: =COUNTIFS(Questions!$B$2:$B$1014,A13,Questions!$F$2:$F$1014,"<>") -> 0 | D13: =IF(B13=0,0,C13/B13) -> 0 | E13: =COUNTIFS(Questions!$B$2:$B$1014,A13,Questions!$H$2:$H$1014,"before launch") -> 27 | F13: =COUNTIFS(Questions!$B$2:$B$1014,A13,Questions!$H$2:$H$1014,"before launch",Questions!$F$2:$F$1014,"<>") -> 0
... A15: AFK pool | B15: =COUNTIF(Questions!$B$2:$B$1014,A15) -> 21 | C15: =COUNTIFS(Questions!$B$2:$B$1014,A15,Questions!$F$2:$F$1014,"<>") -> 0 | D15: =IF(B15=0,0,C15/B15) -> 0 | E15: =COUNTIFS(Questions!$B$2:$B$1014,A15,Questions!$H$2:$H$1014,"before launch") -> 14 | F15: =COUNTIFS(Questions!$B$2:$B$1014,A15,Questions!$H$2:$H$1014,"before launch",Questions!$F$2:$F$1014,"<>") -> 0
A16: Total | B16: =SUM(B2:B15) -> 1013 | C16: =SUM(C2:C15) -> 0 | D16: =IF(B16=0,0,C16/B16) -> 0 | E16: =SUM(E2:E15) -> 390 | F16: =SUM(F2:F15) -> 0

Sheet Questions
A1: # | B1: Area | C1: Feature | D1: Question | E1: Suggested | F1: Your answer | G1: Note | H1: Priority | I1: Context
A2: 1 | B2: Look & feel | C2: Colors and lores (V2) | D2: Show sell price lines in red in item tooltips? | E2: Yes, red | H2: before launch
A3: 2 | B3: Look & feel | C3: Colors and lores (V2) | D3: Show action lines in bold yellow, like '» RIGHT-CLICK buy 64'? | E3: Yes, bold yellow | H3: before launch
A4: 3 | B4: Look & feel | C4: Colors and lores (V2) | D4: Put the thin red bar on every line inside a tooltip section? | E4: Yes, every line | H4: before launch
A5: 4 | B5: Look & feel | C5: Look & feel (colors, lores, menus) | D5: Should the big-sale chat message apply to every /sell sale, not only the sell chest? | E5: Yes, all sales | H5: can wait
A6: 5 | B6: Look & feel | C6: Look & feel (colors, lores, menus) | D6: If a player switches profile with the sell chest open, keep their items for that profile? | E6: Yes, never lost | H6: before launch | I6: Items return at the next switch back.
A7: 6 | B7: Look & feel | C7: Look & feel (colors, lores, menus) | D7: Should 'Sell inventory' keep tools, weapons and armor in the hotbar? | E7: Yes, keep them | H7: before launch
A8: 7 | B8: Look & feel | C8: Look & feel (colors, lores, menus) | D8: If returned items don't fit the inventory, put them in the ender chest first, then drop them? | E8: Yes | H8: before launch
A9: 8 | B9: Look & feel | C9: Look & feel (colors, lores, menus) | D9: Should shop quick-buy ask for confirmation only for purchases of $100k or more? | E9: Yes, $100k | H9: before launch
A10: 9 | B10: Look & feel | C10: Look & feel (colors, lores, menus) | D10: If a player can't afford 64 items, refuse the purchase instead of buying what they can afford? | E10: Yes, refuse | H10: before launch
A11: 10 | B11: Look & feel | C11: Look & feel (colors, lores, menus) | D11: Add a quick 'Buy 1' option for Bedrock players too? | E11: No, amount screen only | H11: can wait
A12: 11 | B12: Look & feel | C12: Look & feel (colors, lores, menus) | D12: Should players be able to drag satchel items into the sell chest? | E12: No, sell them from the satchel | H12: can wait
A13: 12 | B13: Look & feel | C13: Look & feel (colors, lores, menus) | D13: Keep the server's main color red on Bedrock, the same as errors? | E13: Yes, red | H13: can wait | I13: Errors still differ by the ✘ mark.
A14: 13 | B14: Look & feel | C14: Look & feel (colors, lores, menus) | D14: Should the shop's sell price be shown before the player's own sell bonus? | E14: Yes, before bonus | H14: can wait
A15: 14 | B15: Look & feel | C15: Look & feel (colors, lores, menus) | D15: Is the island scoreboard fine with no blank line, and Depths boards showing money only? | E15: Yes, as built | H15: can wait
A16: 15 | B16: Look & feel | C16: Look & feel (colors, lores, menus) | D16: Keep the scoreboard footer in ice blue? | E16: Yes, ice blue | H16: can wait
A17: 16 | B17: Look & feel | C17: Look & feel (colors, lores, menus) | D17: Use yellow-gold for filled progress dots rather than orange? | E17: Yes, yellow-gold | H17: can wait
A18: 17 | B18: Look & feel | C18: Look & feel (colors, lores, menus) | D18: Let item descriptions wrap over up to 3 lines instead of 2? | E18: Yes, 3 lines | H18: can wait
A19: 18 | B19: Look & feel | C19: Look & feel (colors, lores, menus) | D19: Move all menu lore into one shared code builder later? | E19: No, the look already matches | H19: can wait
A20: 19 | B20: Look & feel | C20: Look & feel (colors, lores, menus) | D20: Is it OK that crate, quest and leaderboard holograms come later? | E20: Yes | H20: can wait
A21: 20 | B21: Look & feel | C21: Look & feel (colors, lores, menus) | D21: Keep scoreboard text in the message files, like all other player text? | E21: Yes | H21: can wait
A22: 21 | B22: Look & feel | C22: Look & feel (colors, lores, menus) | D22: Should coop players see the visitor scoreboard on the island they are cooped to? | E22: Yes, visitor board | H22: can wait
A23: 22 | B23: Look & feel | C23: Look & feel (colors, lores, menus) | D23: On someone else's island, show only the island name on the scoreboard? | E23: Yes, island name only | H23: can wait
A24: 23 | B24: Look & feel | C24: Look & feel (colors, lores, menus) | D24: Keep Gems on the island scoreboard, with the 'Next' note line only when there is a note? | E24: Yes | H24: can wait
A25: 24 | B25: Look & feel | C25: Look & feel (colors, lores, menus) | D25: Keep the Depths scoreboard choosing its zone layout from the zone name text? | E25: Yes, text match | H25: can wait
... A27: 26 | B27: Look & feel | C27: Look & feel (colors, lores, menus) | D27: Use aqua ◆ for crystals and green ✦ for gems, with new menu icons? | E27: Yes | H27: can wait
A28: 27 | B28: Look & feel | C28: Look & feel (colors, lores, menus) | D28: Build the crystal island shop and missions later, with the island upgrades? | E28: Yes | H28: can wait | I28: Crystals are only a balance for now.
A29: 28 | B29: Look & feel | C29: Look & feel (colors, lores, menus) | D29: Show SKYBORN in the tab list as white on the left and blue 'MC' on the right? | E29: Yes | H29: can wait
A30: 29 | B30: Look & feel | C30: Look & feel (colors, lores, menus) | D30: Keep the 'Next' objective and online count off the scoreboard for now? | E30: Yes, objective returns with quests | H30: can wait
A31: 30 | B31: Look & feel | C31: Look & feel (colors, lores, menus) | D31: Show join and quit as just [+] Name and [-] Name? | E31: Yes | H31: can wait
A32: 31 | B32: Look & feel | C32: Look and feel V2 (colors, lore, menus, scoreboard) | D32: Launch with English only and add Norwegian later? | E32: Yes, English only at launch | H32: before launch | I32: Translating all messages is a big task.
A33: 32 | B33: Look & feel | C33: Look and feel V2 (colors, lore, menus, scoreboard) | D33: Show big numbers short in menus (1.2M) and in full in chat and /bal? | E33: Yes | H33: before launch
A34: 33 | B34: Look & feel | C34: Look and feel V2 (colors, lore, menus, scoreboard) | D34: Use normal chest menus for Bedrock players too, not special pop-up forms? | E34: Yes, chest menus everywhere | H34: before launch
A35: 34 | B35: Look & feel | C35: Look and feel V2 (colors, lore, menus, scoreboard) | D35: Use a compact, shorter item lore for Bedrock phone players? | E35: Yes, compact mode | H35: before launch
A36: 35 | B36: Look & feel | C36: Look and feel V2 (colors, lore, menus, scoreboard) | D36: Add a high-contrast or color-blind mode in /settings later? | E36: Yes, later | H36: can wait
A37: 36 | B37: Look & feel | C37: Look and feel V2 (colors, lore, menus, scoreboard) | D37: Let players hide single scoreboard lines, such as gems? | E37: Yes, a toggle per line | H37: can wait
A38: 37 | B38: Look & feel | C38: Look and feel V2 (colors, lore, menus, scoreboard) | D38: Add seasonal color palettes, such as a December theme? | E38: Yes, small color swaps | H38: can wait
A39: 38 | B39: Look & feel | C39: Look and feel V2 (colors, lore, menus, scoreboard) | D39: Set menu click sounds to 50% volume for new players? | E39: Yes, 50% | H39: can wait
A40: 39 | B40: Look & feel | C40: Look and feel V2 (colors, lore, menus, scoreboard) | D40: Open the Help page automatically the first time a player joins? | E40: Yes, only once | H40: can wait
A41: 40 | B41: Look & feel | C41: Look and feel V2 (colors, lore, menus, scoreboard) | D41: Show every money change on the action bar, grouped every 1.5 seconds? | E41: Yes | H41: can wait
...
